Workbook

Sheet Dashboard
B1: Online Retail II | Sales Performance Dashboard
B2: UK online gift retailer | 1 Dec 2009 - 9 Dec 2011 | Currency GBP (£) | Net revenue = sales minus cancellations | Pick filters in the yellow cells
B4: COUNTRY ▸ | C4: All Countries | G4: YEAR ▸ | H4: All Years | K4: TREND METRIC ▸ | L4: Net Revenue | N4: ◂ Click a yellow cell, then the drop-down arrow. Everything updates instantly.
B7: NET REVENUE | D7: ORDERS | F7: AVG ORDER VALUE | H7: UNITS SOLD | J7: ACTIVE CUSTOMERS | L7: RETURN RATE | N7: REVENUE / CUSTOMER | P7: ITEMS / ORDER
B8: =Calc!$C$23 -> 18926477 | D8: =Calc!$C$24 -> 39516 | F8: =Calc!$C$26 -> 497.08517 | H8: =Calc!$C$25 -> 11187324 | J8: =Calc!$C$28 -> 5838 | L8: =Calc!$C$27 -> 0.036468318 | N8: =Calc!$C$31 -> 2802.4371 | P8: =Calc!$C$32 -> 283.10872
B10: =Calc!$C$48 -> Dec 2009 - Dec 2011 | D10: =Calc!$C$49 -> Dec 2009 - Dec 2011 | F10: =Calc!$C$50 -> Dec 2009 - Dec 2011 | H10: =Calc!$C$51 -> Dec 2009 - Dec 2011 | J10: =Calc!$C$52 -> Unique buyers with a Customer ID | L10: =Calc!$C$53 -> Returns value: £716,341 | N10: =Calc!$C$54 -> Identified customers only | P10: =Calc!$C$55 -> Units sold / orders
B12: ="Monthly trend | "&Dashboard!$L$4&" | "&Calc!$C$8&" (all months)" -> Monthly trend | Net Revenue | All countries (all months) | J12: ="Net revenue by calendar month, 2010 vs 2011 | "&Calc!$C$8&" (Dec 2011 partial)" -> Net revenue by calendar month, 2010 vs 2011 | All countries (Dec 2011 partial)
B30: ="Top 10 international markets | "&Calc!$C$7&" | UK = "&TEXT(Calc!$C$148,"0%")&" of net revenue" -> Top 10 international markets | All years | UK = 85% of net revenue | J30: ="Top 10 products by net revenue | "&Calc!$C$7&" | "&Calc!$C$8 -> Top 10 products by net revenue | All years | All countries
B50: ="Customer segments (RFM, all-time) | "&Calc!$C$8 -> Customer segments (RFM, all-time) | All countries | H50: ="Top 10 customers | "&Calc!$C$7&" | "&Calc!$C$8 -> Top 10 customers | All years | All countries
H51: # | I51: Customer | J51: Country | L51: Net revenue | N51: Orders | O51: Last order | P51: Segment
H52: =Calc!$B$693 -> 1 | I52: =Calc!$D$693 -> 18102 | J52: =Calc!$E$693 -> United Kingdom | L52: =Calc!$F$693 -> 578408.64 | N52: =Calc!$G$693 -> 145 | O52: =Calc!$H$693 -> 40886 | P52: =Calc!$I$693 -> Champions
H53: =Calc!$B$694 -> 2 | I53: =Calc!$D$694 -> 14646 | J53: =Calc!$E$694 -> Netherlands | L53: =Calc!$F$694 -> 523202.74 | N53: =Calc!$G$694 -> 145 | O53: =Calc!$H$694 -> 40885 | P53: =Calc!$I$694 -> Champions
H54: =Calc!$B$695 -> 3 | I54: =Calc!$D$695 -> 14156 | J54: =Calc!$E$695 -> EIRE | L54: =Calc!$F$695 -> 297775.01 | N54: =Calc!$G$695 -> 144 | O54: =Calc!$H$695 -> 40877 | P54: =Calc!$I$695 -> Champions
H55: =Calc!$B$696 -> 4 | I55: =Calc!$D$696 -> 14911 | J55: =Calc!$E$696 -> EIRE | L55: =Calc!$F$696 -> 258522.43 | N55: =Calc!$G$696 -> 373 | O55: =Calc!$H$696 -> 40885 | P55: =Calc!$I$696 -> Champions
H56: =Calc!$B$697 -> 5 | I56: =Calc!$D$697 -> 17450 | J56: =Calc!$E$697 -> United Kingdom | L56: =Calc!$F$697 -> 233643.91 | N56: =Calc!$G$697 -> 51 | O56: =Calc!$H$697 -> 40878 | P56: =Calc!$I$697 -> Champions
H57: =Calc!$B$698 -> 6 | I57: =Calc!$D$698 -> 13694 | J57: =Calc!$E$698 -> United Kingdom | L57: =Calc!$F$698 -> 190391.5 | N57: =Calc!$G$698 -> 143 | O57: =Calc!$H$698 -> 40883 | P57: =Calc!$I$698 -> Champions
H58: =Calc!$B$699 -> 7 | I58: =Calc!$D$699 -> 17511 | J58: =Calc!$E$699 -> United Kingdom | L58: =Calc!$F$699 -> 168504.44 | N58: =Calc!$G$699 -> 60 | O58: =Calc!$H$699 -> 40884 | P58: =Calc!$I$699 -> Champions
H59: =Calc!$B$700 -> 8 | I59: =Calc!$D$700 -> 12415 | J59: =Calc!$E$700 -> Australia | L59: =Calc!$F$700 -> 143107.02 | N59: =Calc!$G$700 -> 24 | O59: =Calc!$H$700 -> 40862 | P59: =Calc!$I$700 -> Champions
H60: =Calc!$B$701 -> 9 | I60: =Calc!$D$701 -> 16684 | J60: =Calc!$E$701 -> United Kingdom | L60: =Calc!$F$701 -> 141530.29 | N60: =Calc!$G$701 -> 55 | O60: =Calc!$H$701 -> 40882 | P60: =Calc!$I$701 -> Champions
H61: =Calc!$B$702 -> 10 | I61: =Calc!$D$702 -> 15061 | J61: =Calc!$E$702 -> United Kingdom | L61: =Calc!$F$702 -> 124982.13 | N61: =Calc!$G$702 -> 127 | O61: =Calc!$H$702 -> 40883 | P61: =Calc!$I$702 -> Champions
H63: Segment | K63: Customers | L63: % cust. | M63: Net revenue | O63: % rev. | P63: Avg rev / cust.
H64: =Calc!$B$683 -> Champions | K64: =Calc!$C$683 -> 1087 | L64: =Calc!$D$683 -> 0.18574846 | M64: =Calc!$E$683 -> 9727253.6 | O64: =Calc!$F$683 -> 0.5946089 | P64: =Calc!$G$683 -> 8948.7154
H65: =Calc!$B$684 -> Loyal | K65: =Calc!$C$684 -> 806 | L65: =Calc!$D$684 -> 0.13773069 | M65: =Calc!$E$684 -> 2902395.5 | O65: =Calc!$F$684 -> 0.17741803 | P65: =Calc!$G$684 -> 3600.987
H66: =Calc!$B$685 -> Recent / New | K66: =Calc!$C$685 -> 1048 | L66: =Calc!$D$685 -> 0.17908407 | M66: =Calc!$E$685 -> 713380.37 | O66: =Calc!$F$685 -> 0.043607614 | P66: =Calc!$G$685 -> 680.70646
H67: =Calc!$B$686 -> At Risk | K67: =Calc!$C$686 -> 737 | L67: =Calc!$D$686 -> 0.12593985 | M67: =Calc!$E$686 -> 1857884.8 | O67: =Calc!$F$686 -> 0.11356904 | P67: =Calc!$G$686 -> 2520.8749
H68: =Calc!$B$687 -> Hibernating / Lost | K68: =Calc!$C$687 -> 2174 | L68: =Calc!$D$687 -> 0.37149692 | M68: =Calc!$E$687 -> 1158164 | O68: =Calc!$F$687 -> 0.070796407 | P68: =Calc!$G$687 -> 532.73412
H69: =Calc!$B$688 -> Total | K69: =Calc!$C$688 -> 5852 | L69: =Calc!$D$688 -> 1 | M69: =Calc!$E$688 -> 16359078 | O69: =Calc!$F$688 -> 1 | P69: =Calc!$G$688 -> 2795.4679
H70: Segments: Champions = bought in the last ~month & 4+ orders | Loyal | Recent / New = recent, 1-3 orders | At Risk = lapsed, 4+ orders | Hibernating / Lost
B71: ="When customers buy: gross sales by weekday and hour (£k) | "&Calc!$C$7&" | "&Calc!$C$8 -> When customers buy: gross sales by weekday and hour (£k) | All years | All countries
B72: Day \ Hour | C72: 6 | D72: 7 | E72: 8 | F72: 9 | G72: 10 | H72: 11 | I72: 12 | J72: 13 | K72: 14 | L72: 15 | M72: 16 | N72: 17 | O72: 18 | P72: 19 | Q72: 20
B73: Mon | C73: =SUMIFS(Fact_Time!$E$2:$E$1485,Fact_Time!$B$2:$B$1485,Calc!$C$4,Fact_Time!$A$2:$A$1485,">="&Calc!$C$2,Fact_Time!$A$2:$A$1485,"<="&Calc!$C$3,Fact_Time!$C$2:$C$1485,1,Fact_Time!$D$2:$D$1485,C$72) -> 0 | D73: =SUMIFS(Fact_Time!$E$2:$E$1485,Fact_Time!$B$2:$B$1485,Calc!$C$4,Fact_Time!$A$2:$A$1485,">="&Calc!$C$2,Fact_Time!$A$2:$A$1485,"<="&Calc!$C$3,Fact_Time!$C$2:$C$1485,1,Fact_Time!$D$2:$D$1485,D$72) -> 15830.42 | E73: =SUMIFS(Fact_Time!$E$2:$E$1485,Fact_Time!$B$2:$B$1485,Calc!$C$4,Fact_Time!$A$2:$A$1485,">="&Calc!$C$2,Fact_Time!$A$2:$A$1485,"<="&Calc!$C$3,Fact_Time!$C$2:$C$1485,1,Fact_Time!$D$2:$D$1485,E$72) -> 90011.64 | F73: =SUMIFS(Fact_Time!$E$2:$E$1485,Fact_Time!$B$2:$B$1485,Calc!$C$4,Fact_Time!$A$2:$A$1485,">="&Calc!$C$2,Fact_Time!$A$2:$A$1485,"<="&Calc!$C$3,Fact_Time!$C$2:$C$1485,1,Fact_Time!$D$2:$D$1485,F$72) -> 301603.8 | G73: =SUMIFS(Fact_Time!$E$2:$E$1485,Fact_Time!$B$2:$B$1485,Calc!$C$4,Fact_Time!$A$2:$A$1485,">="&Calc!$C$2,Fact_Time!$A$2:$A$1485,"<="&Calc!$C$3,Fact_Time!$C$2:$C$1485,1,Fact_Time!$D$2:$D$1485,G$72) -> 403873.59 | H73: =SUMIFS(Fact_Time!$E$2:$E$1485,Fact_Time!$B$2:$B$1485,Calc!$C$4,Fact_Time!$A$2:$A$1485,">="&Calc!$C$2,Fact_Time!$A$2:$A$1485,"<="&Calc!$C$3,Fact_Time!$C$2:$C$1485,1,Fact_Time!$D$2:$D$1485,H$72) -> 372438.55 | I73: =SUMIFS(Fact_Time!$E$2:$E$1485,Fact_Time!$B$2:$B$1485,Calc!$C$4,Fact_Time!$A$2:$A$1485,">="&Calc!$C$2,Fact_Time!$A$2:$A$1485,"<="&Calc!$C$3,Fact_Time!$C$2:$C$1485,1,Fact_Time!$D$2:$D$1485,I$72) -> 424289.48 | J73: =SUMIFS(Fact_Time!$E$2:$E$1485,Fact_Time!$B$2:$B$1485,Calc!$C$4,Fact_Time!$A$2:$A$1485,">="&Calc!$C$2,Fact_Time!$A$2:$A$1485,"<="&Calc!$C$3,Fact_Time!$C$2:$C$1485,1,Fact_Time!$D$2:$D$1485,J$72) -> 467749.11 | ... Q73: =SUMIFS(Fact_Time!$E$2:$E$1485,Fact_Time!$B$2:$B$1485,Calc!$C$4,Fact_Time!$A$2:$A$1485,">="&Calc!$C$2,Fact_Time!$A$2:$A$1485,"<="&Calc!$C$3,Fact_Time!$C$2:$C$1485,1,Fact_Time!$D$2:$D$1485,Q$72) -> 0
B74: Tue | C74: =SUMIFS(Fact_Time!$E$2:$E$1485,Fact_Time!$B$2:$B$1485,Calc!$C$4,Fact_Time!$A$2:$A$1485,">="&Calc!$C$2,Fact_Time!$A$2:$A$1485,"<="&Calc!$C$3,Fact_Time!$C$2:$C$1485,2,Fact_Time!$D$2:$D$1485,C$72) -> 0 | D74: =SUMIFS(Fact_Time!$E$2:$E$1485,Fact_Time!$B$2:$B$1485,Calc!$C$4,Fact_Time!$A$2:$A$1485,">="&Calc!$C$2,Fact_Time!$A$2:$A$1485,"<="&Calc!$C$3,Fact_Time!$C$2:$C$1485,2,Fact_Time!$D$2:$D$1485,D$72) -> 11442.26 | E74: =SUMIFS(Fact_Time!$E$2:$E$1485,Fact_Time!$B$2:$B$1485,Calc!$C$4,Fact_Time!$A$2:$A$1485,">="&Calc!$C$2,Fact_Time!$A$2:$A$1485,"<="&Calc!$C$3,Fact_Time!$C$2:$C$1485,2,Fact_Time!$D$2:$D$1485,E$72) -> 116972.72 | F74: =SUMIFS(Fact_Time!$E$2:$E$1485,Fact_Time!$B$2:$B$1485,Calc!$C$4,Fact_Time!$A$2:$A$1485,">="&Calc!$C$2,Fact_Time!$A$2:$A$1485,"<="&Calc!$C$3,Fact_Time!$C$2:$C$1485,2,Fact_Time!$D$2:$D$1485,F$72) -> 337150.62 | G74: =SUMIFS(Fact_Time!$E$2:$E$1485,Fact_Time!$B$2:$B$1485,Calc!$C$4,Fact_Time!$A$2:$A$1485,">="&Calc!$C$2,Fact_Time!$A$2:$A$1485,"<="&Calc!$C$3,Fact_Time!$C$2:$C$1485,2,Fact_Time!$D$2:$D$1485,G$72) -> 536991.35 | H74: =SUMIFS(Fact_Time!$E$2:$E$1485,Fact_Time!$B$2:$B$1485,Calc!$C$4,Fact_Time!$A$2:$A$1485,">="&Calc!$C$2,Fact_Time!$A$2:$A$1485,"<="&Calc!$C$3,Fact_Time!$C$2:$C$1485,2,Fact_Time!$D$2:$D$1485,H$72) -> 516149.6 | I74: =SUMIFS(Fact_Time!$E$2:$E$1485,Fact_Time!$B$2:$B$1485,Calc!$C$4,Fact_Time!$A$2:$A$1485,">="&Calc!$C$2,Fact_Time!$A$2:$A$1485,"<="&Calc!$C$3,Fact_Time!$C$2:$C$1485,2,Fact_Time!$D$2:$D$1485,I$72) -> 498808.04 | J74: =SUMIFS(Fact_Time!$E$2:$E$1485,Fact_Time!$B$2:$B$1485,Calc!$C$4,Fact_Time!$A$2:$A$1485,">="&Calc!$C$2,Fact_Time!$A$2:$A$1485,"<="&Calc!$C$3,Fact_Time!$C$2:$C$1485,2,Fact_Time!$D$2:$D$1485,J$72) -> 477883.49 | ... Q74: =SUMIFS(Fact_Time!$E$2:$E$1485,Fact_Time!$B$2:$B$1485,Calc!$C$4,Fact_Time!$A$2:$A$1485,">="&Calc!$C$2,Fact_Time!$A$2:$A$1485,"<="&Calc!$C$3,Fact_Time!$C$2:$C$1485,2,Fact_Time!$D$2:$D$1485,Q$72) -> 661.8
B75: Wed | C75: =SUMIFS(Fact_Time!$E$2:$E$1485,Fact_Time!$B$2:$B$1485,Calc!$C$4,Fact_Time!$A$2:$A$1485,">="&Calc!$C$2,Fact_Time!$A$2:$A$1485,"<="&Calc!$C$3,Fact_Time!$C$2:$C$1485,3,Fact_Time!$D$2:$D$1485,C$72) -> 0 | D75: =SUMIFS(Fact_Time!$E$2:$E$1485,Fact_Time!$B$2:$B$1485,Calc!$C$4,Fact_Time!$A$2:$A$1485,">="&Calc!$C$2,Fact_Time!$A$2:$A$1485,"<="&Calc!$C$3,Fact_Time!$C$2:$C$1485,3,Fact_Time!$D$2:$D$1485,D$72) -> 10110.76 | E75: =SUMIFS(Fact_Time!$E$2:$E$1485,Fact_Time!$B$2:$B$1485,Calc!$C$4,Fact_Time!$A$2:$A$1485,">="&Calc!$C$2,Fact_Time!$A$2:$A$1485,"<="&Calc!$C$3,Fact_Time!$C$2:$C$1485,3,Fact_Time!$D$2:$D$1485,E$72) -> 87349.59 | F75: =SUMIFS(Fact_Time!$E$2:$E$1485,Fact_Time!$B$2:$B$1485,Calc!$C$4,Fact_Time!$A$2:$A$1485,">="&Calc!$C$2,Fact_Time!$A$2:$A$1485,"<="&Calc!$C$3,Fact_Time!$C$2:$C$1485,3,Fact_Time!$D$2:$D$1485,F$72) -> 287427.38 | G75: =SUMIFS(Fact_Time!$E$2:$E$1485,Fact_Time!$B$2:$B$1485,Calc!$C$4,Fact_Time!$A$2:$A$1485,">="&Calc!$C$2,Fact_Time!$A$2:$A$1485,"<="&Calc!$C$3,Fact_Time!$C$2:$C$1485,3,Fact_Time!$D$2:$D$1485,G$72) -> 473635.88 | H75: =SUMIFS(Fact_Time!$E$2:$E$1485,Fact_Time!$B$2:$B$1485,Calc!$C$4,Fact_Time!$A$2:$A$1485,">="&Calc!$C$2,Fact_Time!$A$2:$A$1485,"<="&Calc!$C$3,Fact_Time!$C$2:$C$1485,3,Fact_Time!$D$2:$D$1485,H$72) -> 415380.88 | I75: =SUMIFS(Fact_Time!$E$2:$E$1485,Fact_Time!$B$2:$B$1485,Calc!$C$4,Fact_Time!$A$2:$A$1485,">="&Calc!$C$2,Fact_Time!$A$2:$A$1485,"<="&Calc!$C$3,Fact_Time!$C$2:$C$1485,3,Fact_Time!$D$2:$D$1485,I$72) -> 552585.49 | J75: =SUMIFS(Fact_Time!$E$2:$E$1485,Fact_Time!$B$2:$B$1485,Calc!$C$4,Fact_Time!$A$2:$A$1485,">="&Calc!$C$2,Fact_Time!$A$2:$A$1485,"<="&Calc!$C$3,Fact_Time!$C$2:$C$1485,3,Fact_Time!$D$2:$D$1485,J$72) -> 433390.62 | ... Q75: =SUMIFS(Fact_Time!$E$2:$E$1485,Fact_Time!$B$2:$B$1485,Calc!$C$4,Fact_Time!$A$2:$A$1485,">="&Calc!$C$2,Fact_Time!$A$2:$A$1485,"<="&Calc!$C$3,Fact_Time!$C$2:$C$1485,3,Fact_Time!$D$2:$D$1485,Q$72) -> 13031.5
B76: Thu | C76: =SUMIFS(Fact_Time!$E$2:$E$1485,Fact_Time!$B$2:$B$1485,Calc!$C$4,Fact_Time!$A$2:$A$1485,">="&Calc!$C$2,Fact_Time!$A$2:$A$1485,"<="&Calc!$C$3,Fact_Time!$C$2:$C$1485,4,Fact_Time!$D$2:$D$1485,C$72) -> 4.25 | D76: =SUMIFS(Fact_Time!$E$2:$E$1485,Fact_Time!$B$2:$B$1485,Calc!$C$4,Fact_Time!$A$2:$A$1485,">="&Calc!$C$2,Fact_Time!$A$2:$A$1485,"<="&Calc!$C$3,Fact_Time!$C$2:$C$1485,4,Fact_Time!$D$2:$D$1485,D$72) -> 15991.41 | E76: =SUMIFS(Fact_Time!$E$2:$E$1485,Fact_Time!$B$2:$B$1485,Calc!$C$4,Fact_Time!$A$2:$A$1485,">="&Calc!$C$2,Fact_Time!$A$2:$A$1485,"<="&Calc!$C$3,Fact_Time!$C$2:$C$1485,4,Fact_Time!$D$2:$D$1485,E$72) -> 120462.54 | F76: =SUMIFS(Fact_Time!$E$2:$E$1485,Fact_Time!$B$2:$B$1485,Calc!$C$4,Fact_Time!$A$2:$A$1485,">="&Calc!$C$2,Fact_Time!$A$2:$A$1485,"<="&Calc!$C$3,Fact_Time!$C$2:$C$1485,4,Fact_Time!$D$2:$D$1485,F$72) -> 313148.14 | G76: =SUMIFS(Fact_Time!$E$2:$E$1485,Fact_Time!$B$2:$B$1485,Calc!$C$4,Fact_Time!$A$2:$A$1485,">="&Calc!$C$2,Fact_Time!$A$2:$A$1485,"<="&Calc!$C$3,Fact_Time!$C$2:$C$1485,4,Fact_Time!$D$2:$D$1485,G$72) -> 488706.11 | H76: =SUMIFS(Fact_Time!$E$2:$E$1485,Fact_Time!$B$2:$B$1485,Calc!$C$4,Fact_Time!$A$2:$A$1485,">="&Calc!$C$2,Fact_Time!$A$2:$A$1485,"<="&Calc!$C$3,Fact_Time!$C$2:$C$1485,4,Fact_Time!$D$2:$D$1485,H$72) -> 418753.15 | I76: =SUMIFS(Fact_Time!$E$2:$E$1485,Fact_Time!$B$2:$B$1485,Calc!$C$4,Fact_Time!$A$2:$A$1485,">="&Calc!$C$2,Fact_Time!$A$2:$A$1485,"<="&Calc!$C$3,Fact_Time!$C$2:$C$1485,4,Fact_Time!$D$2:$D$1485,I$72) -> 528170.55 | J76: =SUMIFS(Fact_Time!$E$2:$E$1485,Fact_Time!$B$2:$B$1485,Calc!$C$4,Fact_Time!$A$2:$A$1485,">="&Calc!$C$2,Fact_Time!$A$2:$A$1485,"<="&Calc!$C$3,Fact_Time!$C$2:$C$1485,4,Fact_Time!$D$2:$D$1485,J$72) -> 401124.48 | ... Q76: =SUMIFS(Fact_Time!$E$2:$E$1485,Fact_Time!$B$2:$B$1485,Calc!$C$4,Fact_Time!$A$2:$A$1485,">="&Calc!$C$2,Fact_Time!$A$2:$A$1485,"<="&Calc!$C$3,Fact_Time!$C$2:$C$1485,4,Fact_Time!$D$2:$D$1485,Q$72) -> 25175.4
B77: Fri | C77: =SUMIFS(Fact_Time!$E$2:$E$1485,Fact_Time!$B$2:$B$1485,Calc!$C$4,Fact_Time!$A$2:$A$1485,">="&Calc!$C$2,Fact_Time!$A$2:$A$1485,"<="&Calc!$C$3,Fact_Time!$C$2:$C$1485,5,Fact_Time!$D$2:$D$1485,C$72) -> 0 | D77: =SUMIFS(Fact_Time!$E$2:$E$1485,Fact_Time!$B$2:$B$1485,Calc!$C$4,Fact_Time!$A$2:$A$1485,">="&Calc!$C$2,Fact_Time!$A$2:$A$1485,"<="&Calc!$C$3,Fact_Time!$C$2:$C$1485,5,Fact_Time!$D$2:$D$1485,D$72) -> 21654.72 | E77: =SUMIFS(Fact_Time!$E$2:$E$1485,Fact_Time!$B$2:$B$1485,Calc!$C$4,Fact_Time!$A$2:$A$1485,">="&Calc!$C$2,Fact_Time!$A$2:$A$1485,"<="&Calc!$C$3,Fact_Time!$C$2:$C$1485,5,Fact_Time!$D$2:$D$1485,E$72) -> 107153.71 | F77: =SUMIFS(Fact_Time!$E$2:$E$1485,Fact_Time!$B$2:$B$1485,Calc!$C$4,Fact_Time!$A$2:$A$1485,">="&Calc!$C$2,Fact_Time!$A$2:$A$1485,"<="&Calc!$C$3,Fact_Time!$C$2:$C$1485,5,Fact_Time!$D$2:$D$1485,F$72) -> 462372.67 | G77: =SUMIFS(Fact_Time!$E$2:$E$1485,Fact_Time!$B$2:$B$1485,Calc!$C$4,Fact_Time!$A$2:$A$1485,">="&Calc!$C$2,Fact_Time!$A$2:$A$1485,"<="&Calc!$C$3,Fact_Time!$C$2:$C$1485,5,Fact_Time!$D$2:$D$1485,G$72) -> 431543.74 | H77: =SUMIFS(Fact_Time!$E$2:$E$1485,Fact_Time!$B$2:$B$1485,Calc!$C$4,Fact_Time!$A$2:$A$1485,">="&Calc!$C$2,Fact_Time!$A$2:$A$1485,"<="&Calc!$C$3,Fact_Time!$C$2:$C$1485,5,Fact_Time!$D$2:$D$1485,H$72) -> 381563.2 | I77: =SUMIFS(Fact_Time!$E$2:$E$1485,Fact_Time!$B$2:$B$1485,Calc!$C$4,Fact_Time!$A$2:$A$1485,">="&Calc!$C$2,Fact_Time!$A$2:$A$1485,"<="&Calc!$C$3,Fact_Time!$C$2:$C$1485,5,Fact_Time!$D$2:$D$1485,I$72) -> 433542.53 | J77: =SUMIFS(Fact_Time!$E$2:$E$1485,Fact_Time!$B$2:$B$1485,Calc!$C$4,Fact_Time!$A$2:$A$1485,">="&Calc!$C$2,Fact_Time!$A$2:$A$1485,"<="&Calc!$C$3,Fact_Time!$C$2:$C$1485,5,Fact_Time!$D$2:$D$1485,J$72) -> 351891.9 | ... Q77: =SUMIFS(Fact_Time!$E$2:$E$1485,Fact_Time!$B$2:$B$1485,Calc!$C$4,Fact_Time!$A$2:$A$1485,">="&Calc!$C$2,Fact_Time!$A$2:$A$1485,"<="&Calc!$C$3,Fact_Time!$C$2:$C$1485,5,Fact_Time!$D$2:$D$1485,Q$72) -> 19.19
B78: Sat | C78: =SUMIFS(Fact_Time!$E$2:$E$1485,Fact_Time!$B$2:$B$1485,Calc!$C$4,Fact_Time!$A$2:$A$1485,">="&Calc!$C$2,Fact_Time!$A$2:$A$1485,"<="&Calc!$C$3,Fact_Time!$C$2:$C$1485,6,Fact_Time!$D$2:$D$1485,C$72) -> 0 | D78: =SUMIFS(Fact_Time!$E$2:$E$1485,Fact_Time!$B$2:$B$1485,Calc!$C$4,Fact_Time!$A$2:$A$1485,">="&Calc!$C$2,Fact_Time!$A$2:$A$1485,"<="&Calc!$C$3,Fact_Time!$C$2:$C$1485,6,Fact_Time!$D$2:$D$1485,D$72) -> 0 | E78: =SUMIFS(Fact_Time!$E$2:$E$1485,Fact_Time!$B$2:$B$1485,Calc!$C$4,Fact_Time!$A$2:$A$1485,">="&Calc!$C$2,Fact_Time!$A$2:$A$1485,"<="&Calc!$C$3,Fact_Time!$C$2:$C$1485,6,Fact_Time!$D$2:$D$1485,E$72) -> 0 | F78: =SUMIFS(Fact_Time!$E$2:$E$1485,Fact_Time!$B$2:$B$1485,Calc!$C$4,Fact_Time!$A$2:$A$1485,">="&Calc!$C$2,Fact_Time!$A$2:$A$1485,"<="&Calc!$C$3,Fact_Time!$C$2:$C$1485,6,Fact_Time!$D$2:$D$1485,F$72) -> 0 | G78: =SUMIFS(Fact_Time!$E$2:$E$1485,Fact_Time!$B$2:$B$1485,Calc!$C$4,Fact_Time!$A$2:$A$1485,">="&Calc!$C$2,Fact_Time!$A$2:$A$1485,"<="&Calc!$C$3,Fact_Time!$C$2:$C$1485,6,Fact_Time!$D$2:$D$1485,G$72) -> 1059.74 | H78: =SUMIFS(Fact_Time!$E$2:$E$1485,Fact_Time!$B$2:$B$1485,Calc!$C$4,Fact_Time!$A$2:$A$1485,">="&Calc!$C$2,Fact_Time!$A$2:$A$1485,"<="&Calc!$C$3,Fact_Time!$C$2:$C$1485,6,Fact_Time!$D$2:$D$1485,H$72) -> 230.2 | I78: =SUMIFS(Fact_Time!$E$2:$E$1485,Fact_Time!$B$2:$B$1485,Calc!$C$4,Fact_Time!$A$2:$A$1485,">="&Calc!$C$2,Fact_Time!$A$2:$A$1485,"<="&Calc!$C$3,Fact_Time!$C$2:$C$1485,6,Fact_Time!$D$2:$D$1485,I$72) -> 2110.65 | J78: =SUMIFS(Fact_Time!$E$2:$E$1485,Fact_Time!$B$2:$B$1485,Calc!$C$4,Fact_Time!$A$2:$A$1485,">="&Calc!$C$2,Fact_Time!$A$2:$A$1485,"<="&Calc!$C$3,Fact_Time!$C$2:$C$1485,6,Fact_Time!$D$2:$D$1485,J$72) -> 2520.49 | ... Q78: =SUMIFS(Fact_Time!$E$2:$E$1485,Fact_Time!$B$2:$B$1485,Calc!$C$4,Fact_Time!$A$2:$A$1485,">="&Calc!$C$2,Fact_Time!$A$2:$A$1485,"<="&Calc!$C$3,Fact_Time!$C$2:$C$1485,6,Fact_Time!$D$2:$D$1485,Q$72) -> 0
B79: Sun | C79: =SUMIFS(Fact_Time!$E$2:$E$1485,Fact_Time!$B$2:$B$1485,Calc!$C$4,Fact_Time!$A$2:$A$1485,">="&Calc!$C$2,Fact_Time!$A$2:$A$1485,"<="&Calc!$C$3,Fact_Time!$C$2:$C$1485,7,Fact_Time!$D$2:$D$1485,C$72) -> 0 | D79: =SUMIFS(Fact_Time!$E$2:$E$1485,Fact_Time!$B$2:$B$1485,Calc!$C$4,Fact_Time!$A$2:$A$1485,">="&Calc!$C$2,Fact_Time!$A$2:$A$1485,"<="&Calc!$C$3,Fact_Time!$C$2:$C$1485,7,Fact_Time!$D$2:$D$1485,D$72) -> 0 | E79: =SUMIFS(Fact_Time!$E$2:$E$1485,Fact_Time!$B$2:$B$1485,Calc!$C$4,Fact_Time!$A$2:$A$1485,">="&Calc!$C$2,Fact_Time!$A$2:$A$1485,"<="&Calc!$C$3,Fact_Time!$C$2:$C$1485,7,Fact_Time!$D$2:$D$1485,E$72) -> 0 | F79: =SUMIFS(Fact_Time!$E$2:$E$1485,Fact_Time!$B$2:$B$1485,Calc!$C$4,Fact_Time!$A$2:$A$1485,">="&Calc!$C$2,Fact_Time!$A$2:$A$1485,"<="&Calc!$C$3,Fact_Time!$C$2:$C$1485,7,Fact_Time!$D$2:$D$1485,F$72) -> 2853.12 | G79: =SUMIFS(Fact_Time!$E$2:$E$1485,Fact_Time!$B$2:$B$1485,Calc!$C$4,Fact_Time!$A$2:$A$1485,">="&Calc!$C$2,Fact_Time!$A$2:$A$1485,"<="&Calc!$C$3,Fact_Time!$C$2:$C$1485,7,Fact_Time!$D$2:$D$1485,G$72) -> 172918.82 | H79: =SUMIFS(Fact_Time!$E$2:$E$1485,Fact_Time!$B$2:$B$1485,Calc!$C$4,Fact_Time!$A$2:$A$1485,">="&Calc!$C$2,Fact_Time!$A$2:$A$1485,"<="&Calc!$C$3,Fact_Time!$C$2:$C$1485,7,Fact_Time!$D$2:$D$1485,H$72) -> 317775.19 | I79: =SUMIFS(Fact_Time!$E$2:$E$1485,Fact_Time!$B$2:$B$1485,Calc!$C$4,Fact_Time!$A$2:$A$1485,">="&Calc!$C$2,Fact_Time!$A$2:$A$1485,"<="&Calc!$C$3,Fact_Time!$C$2:$C$1485,7,Fact_Time!$D$2:$D$1485,I$72) -> 345640.77 | J79: =SUMIFS(Fact_Time!$E$2:$E$1485,Fact_Time!$B$2:$B$1485,Calc!$C$4,Fact_Time!$A$2:$A$1485,">="&Calc!$C$2,Fact_Time!$A$2:$A$1485,"<="&Calc!$C$3,Fact_Time!$C$2:$C$1485,7,Fact_Time!$D$2:$D$1485,J$72) -> 345354.45 | ... Q79: =SUMIFS(Fact_Time!$E$2:$E$1485,Fact_Time!$B$2:$B$1485,Calc!$C$4,Fact_Time!$A$2:$A$1485,">="&Calc!$C$2,Fact_Time!$A$2:$A$1485,"<="&Calc!$C$3,Fact_Time!$C$2:$C$1485,7,Fact_Time!$D$2:$D$1485,Q$72) -> 0
B80: Gross sales only (cancellations excluded). Values in £ thousands; blank = no sales. Saturday trading is negligible.
B82: Data model: Fact_Monthly / Fact_Product / Fact_Time / Customers sheets | Logic: Calc sheet | Definitions & cleaning log: Notes sheet

Sheet Notes
B1: Notes: how to use, definitions, data cleaning and assumptions
B3: HOW TO USE
B4: Filters | C4: On the Dashboard sheet change the three YELLOW cells (Country, Year, Trend metric) using their drop-down arrows. All KPIs, charts and tables recalculate instantly. No macros are needed.
B5: What each filter drives | C5: Country: every panel except the "Top 10 international markets" chart (which compares countries). Year: KPIs, markets, products, top customers, heat map. The monthly trend and 2010-vs-2011 charts always show all months. Segments follow Country only (they are an all-time snapshot).
B6: Sheets | C6: Dashboard (the report) | Calc (all formulas feeding the dashboard) | Customers (one row per customer incl. RFM scoring formulas) | Fact_Monthly, Fact_Product, Fact_Time (pre-aggregated data) | Lists (drop-down sources).
B8: DEFINITIONS
B9: Gross sales | C9: Quantity x Price on normal (non-cancelled) invoices.
B10: Returns / cancellations | C10: Absolute value of lines on invoices starting with "C" (customer cancellations / credit notes).
B11: Net revenue | C11: Gross sales minus returns. Headline revenue figure.
B12: Orders | C12: Unique non-cancelled invoice numbers.
B13: Avg order value | C13: Gross sales / orders.
B14: Return rate | C14: Returns / gross sales (value-based). Returns are dated when processed, so monthly rates can be noisy.
B15: Active customers | C15: Customers with a Customer ID and positive net revenue in the selected country/year.
B16: RFM segments | C16: Recency = days from the snapshot date (Calc!C5) to last order, scored 4 (best) to 1 by quartile. Frequency = order count scored 1-4 using editable cut-offs in Calc!C16:C18. Champions: R=4 & F>=3 | Loyal: R=3 & F>=3 | Recent / New: R>=3 & F<=2 | At Risk: R<=2 & F>=3 | Hibernating / Lost: R<=2 & F<=2.
B17: Customer country | C17: Each customer is assigned the country where they generated the most revenue.
B19: DATA CLEANING LOG (done when the source file was processed)
B20: Rows in source | C20: 1,055,236 rows across the two year sheets (the stray 'Sheet1' pivot in the source file was ignored).
B21: Overlap removed | C21: 22,200 duplicate rows: 1-9 Dec 2010 appears in both year sheets, so it was kept once.
B22: Non-merchandise removed | C22: 5,818 rows: postage, manual adjustments, bank charges, Amazon fees, samples, gift vouchers, test codes, bad-debt adjustment invoices ('A').
B23: Zero / negative price removed | C23: 5,964 rows (stock write-offs, damaged goods, free items).
B24: Other | C24: 7 non-cancel rows with negative quantity removed.
B25: Clean rows analysed | C25: 1,021,247 rows, 01 Dec 2009 to 09 Dec 2011.
B27: ASSUMPTIONS & LIMITATIONS
B28: Partial months | C28: Dec 2009 contains data from 1 Dec only and Dec 2011 ends on 9 Dec, so Year = 2009 and the last point of 2011 are partial periods.
B29: YoY comparison | C29: Card sub-texts show YoY only for Year = 2011, comparing Jan to the last complete month (Calc!C6 = 11, i.e. Nov) of 2011 against 2010 to avoid comparing a partial December.
B30: Missing Customer ID | C30: 227,087 cleaned rows (14% of net revenue) have no Customer ID. They are included in revenue, orders, units, products and the heat map, but excluded from customer counts, RFM and top customers.
B31: Product universe | C31: Product rankings cover the top 500 products by lifetime net revenue (63% of net revenue) to keep the workbook fast.
B32: UK dominance | C32: The UK is the vast majority of revenue, so the country chart ranks international markets (UK excluded); the UK share is shown in its caption.
B33: Refreshing | C33: To rebuild from a newer export, run build_dashboard.py (included) against the new source file.

Sheet Calc
B1: CALC ENGINE - all dashboard numbers are live formulas on the Fact_* sheets. Blue cells = editable assumptions.
B2: Year filter - low | C2: =IFERROR(VALUE(Dashboard!$H$4),0) -> 0
B3: Year filter - high | C3: =IFERROR(VALUE(Dashboard!$H$4),9999) -> 9999
B4: Country criterion ("*" = all) | C4: =IF(Dashboard!$C$4="All Countries","*",Dashboard!$C$4) -> *
B5: Snapshot date for recency (day after last order) | C5: 40887
B6: Last COMPLETE month of 2011 (for YoY comparison) | C6: 11
B7: Year label | C7: =IFERROR(TEXT(VALUE(Dashboard!$H$4),"0"),"All years") -> All years
B8: Country label | C8: =IF(Dashboard!$C$4="All Countries","All countries",Dashboard!$C$4) -> All countries
B10: RFM recency cut-offs (days since last order, quartiles of all customers)
B11: Score 4 if recency <= (25th pct) | C11: =PERCENTILE(Customers!$J$2:$J$5853,0.25) -> 26
B12: Score 3 if recency <= (50th pct) | C12: =PERCENTILE(Customers!$J$2:$J$5853,0.5) -> 96
B13: Score 2 if recency <= (75th pct) | C13: =PERCENTILE(Customers!$J$2:$J$5853,0.75) -> 380
B15: RFM frequency cut-offs (number of orders) - editable
B16: F score +1 at >= orders | C16: 2
B17: F score +1 again at >= orders | C17: 4
B18: F score +1 again at >= orders | C18: 8
B20: KPI calculations (follow Country + Year filters)
B21: Gross sales (£) | C21: =SUMIFS(Fact_Monthly!$E$2:$E$583,Fact_Monthly!$D$2:$D$583,$C$4,Fact_Monthly!$B$2:$B$583,">="&$C$2,Fact_Monthly!$B$2:$B$583,"<="&$C$3) -> 19642818
B22: Returns / cancellations (£) | C22: =SUMIFS(Fact_Monthly!$F$2:$F$583,Fact_Monthly!$D$2:$D$583,$C$4,Fact_Monthly!$B$2:$B$583,">="&$C$2,Fact_Monthly!$B$2:$B$583,"<="&$C$3) -> 716340.52
B23: Net revenue (£) | C23: =C21-C22 -> 18926477
B24: Orders (unique invoices) | C24: =SUMIFS(Fact_Monthly!$G$2:$G$583,Fact_Monthly!$D$2:$D$583,$C$4,Fact_Monthly!$B$2:$B$583,">="&$C$2,Fact_Monthly!$B$2:$B$583,"<="&$C$3) -> 39516
B25: Units sold | C25: =SUMIFS(Fact_Monthly!$H$2:$H$583,Fact_Monthly!$D$2:$D$583,$C$4,Fact_Monthly!$B$2:$B$583,">="&$C$2,Fact_Monthly!$B$2:$B$583,"<="&$C$3) -> 11187324
B26: Avg order value (gross sales / orders) | C26: =IF(C24=0,0,C21/C24) -> 497.08517
B27: Return rate (returns / gross sales) | C27: =IF(C21=0,0,C22/C21) -> 0.036468318
B28: Active customers (with Customer ID) | C28: =COUNTIF(Customers!$O$2:$O$5853,">0") -> 5838
B29: Active customers - all countries | C29: =COUNTIF(Customers!$N$2:$N$5853,">0") -> 5838
B30: Net revenue from identified customers (£) | C30: =SUMIFS(Customers!$N$2:$N$5853,Customers!$B$2:$B$5853,$C$4,Customers!$N$2:$N$5853,">0") -> 16360628
B31: Revenue per active customer (£) | C31: =IF(C28=0,0,C30/C28) -> 2802.4371
B32: Items per order | C32: =IF(C24=0,0,C25/C24) -> 283.10872
B34: Year-over-year comparison, 2011 vs 2010 (same months Jan..last complete month)
B35: Net revenue 2011 (£) | C35: =SUMIFS(Fact_Monthly!$E$2:$E$583,Fact_Monthly!$D$2:$D$583,$C$4,Fact_Monthly!$B$2:$B$583,2011,Fact_Monthly!$C$2:$C$583,"<="&$C$6)-SUMIFS(Fact_Monthly!$F$2:$F$583,Fact_Monthly!$D$2:$D$583,$C$4,Fact_Monthly!$B$2:$B$583,2011,Fact_Monthly!$C$2:$C$583,"<="&$C$6) -> 8572828.1
B36: Net revenue 2010 (£) | C36: =SUMIFS(Fact_Monthly!$E$2:$E$583,Fact_Monthly!$D$2:$D$583,$C$4,Fact_Monthly!$B$2:$B$583,2010,Fact_Monthly!$C$2:$C$583,"<="&$C$6)-SUMIFS(Fact_Monthly!$F$2:$F$583,Fact_Monthly!$D$2:$D$583,$C$4,Fact_Monthly!$B$2:$B$583,2010,Fact_Monthly!$C$2:$C$583,"<="&$C$6) -> 8377774.4
B37: Orders 2011 | C37: =SUMIFS(Fact_Monthly!$G$2:$G$583,Fact_Monthly!$D$2:$D$583,$C$4,Fact_Monthly!$B$2:$B$583,2011,Fact_Monthly!$C$2:$C$583,"<="&$C$6) -> 17407
B38: Orders 2010 | C38: =SUMIFS(Fact_Monthly!$G$2:$G$583,Fact_Monthly!$D$2:$D$583,$C$4,Fact_Monthly!$B$2:$B$583,2010,Fact_Monthly!$C$2:$C$583,"<="&$C$6) -> 18077
B39: Units 2011 | C39: =SUMIFS(Fact_Monthly!$H$2:$H$583,Fact_Monthly!$D$2:$D$583,$C$4,Fact_Monthly!$B$2:$B$583,2011,Fact_Monthly!$C$2:$C$583,"<="&$C$6) -> 4891208
B40: Units 2010 | C40: =SUMIFS(Fact_Monthly!$H$2:$H$583,Fact_Monthly!$D$2:$D$583,$C$4,Fact_Monthly!$B$2:$B$583,2010,Fact_Monthly!$C$2:$C$583,"<="&$C$6) -> 5201442
B41: Gross sales 2011 (£) | C41: =SUMIFS(Fact_Monthly!$E$2:$E$583,Fact_Monthly!$D$2:$D$583,$C$4,Fact_Monthly!$B$2:$B$583,2011,Fact_Monthly!$C$2:$C$583,"<="&$C$6) -> 8857090
B42: Gross sales 2010 (£) | C42: =SUMIFS(Fact_Monthly!$E$2:$E$583,Fact_Monthly!$D$2:$D$583,$C$4,Fact_Monthly!$B$2:$B$583,2010,Fact_Monthly!$C$2:$C$583,"<="&$C$6) -> 8598741.1
B43: Net revenue YoY | C43: =IF(C36=0,"n/a",C35/C36-1) -> 0.02328228
B44: Orders YoY | C44: =IF(C38=0,"n/a",C37/C38-1) -> -0.037063672
...

Sheet Customers
A1: CustomerID | B1: Country | C1: First Order | D1: Last Order | E1: Orders | F1: Net Rev 2009 | G1: Net Rev 2010 | H1: Net Rev 2011 | I1: Total Net Rev | J1: Recency (days) | K1: R Score | L1: F Score | M1: Segment | N1: Rev (selected year) | O1: Rank key
A2: 12346 | B2: United Kingdom | C2: 40239 | D2: 40561 | E2: 3 | F2: 0 | G2: 169.36 | H2: 0 | I2: =SUM(F2:H2) -> 169.36 | J2: =Calc!$C$5-D2 -> 326 | K2: =IF(J2<=Calc!$C$11,4,IF(J2<=Calc!$C$12,3,IF(J2<=Calc!$C$13,2,1))) -> 2 | L2: =1+(E2>=Calc!$C$16)+(E2>=Calc!$C$17)+(E2>=Calc!$C$18) -> 2 | M2: =IF(AND(K2=4,L2>=3),"Champions",IF(AND(K2=3,L2>=3),"Loyal",IF(K2>=3,"Recent / New",IF(L2>=3,"At Risk","Hibernating / Lost")))) -> Hibernating / Lost | N2: =IF(AND(Calc!$C$2<=2009,Calc!$C$3>=2009),F2,0)+IF(AND(Calc!$C$2<=2010,Calc!$C$3>=2010),G2,0)+IF(AND(Calc!$C$2<=2011,Calc!$C$3>=2011),H2,0) -> 169.36 | O2: =IF(AND(N2>0,OR(Calc!$C$4="*",B2=Calc!$C$4)),N2+ROW()*0.000000001,0) -> 169.36
A3: 12347 | B3: Iceland | C3: 40482 | D3: 40884 | E3: 8 | F3: 0 | G3: 1323.32 | H3: 3598.21 | I3: =SUM(F3:H3) -> 4921.53 | J3: =Calc!$C$5-D3 -> 3 | K3: =IF(J3<=Calc!$C$11,4,IF(J3<=Calc!$C$12,3,IF(J3<=Calc!$C$13,2,1))) -> 4 | L3: =1+(E3>=Calc!$C$16)+(E3>=Calc!$C$17)+(E3>=Calc!$C$18) -> 4 | M3: =IF(AND(K3=4,L3>=3),"Champions",IF(AND(K3=3,L3>=3),"Loyal",IF(K3>=3,"Recent / New",IF(L3>=3,"At Risk","Hibernating / Lost")))) -> Champions | N3: =IF(AND(Calc!$C$2<=2009,Calc!$C$3>=2009),F3,0)+IF(AND(Calc!$C$2<=2010,Calc!$C$3>=2010),G3,0)+IF(AND(Calc!$C$2<=2011,Calc!$C$3>=2011),H3,0) -> 4921.53 | O3: =IF(AND(N3>0,OR(Calc!$C$4="*",B3=Calc!$C$4)),N3+ROW()*0.000000001,0) -> 4921.53
A4: 12348 | B4: Finland | C4: 40448 | D4: 40811 | E4: 5 | F4: 0 | G4: 873.96 | H4: 784.44 | I4: =SUM(F4:H4) -> 1658.4 | J4: =Calc!$C$5-D4 -> 76 | K4: =IF(J4<=Calc!$C$11,4,IF(J4<=Calc!$C$12,3,IF(J4<=Calc!$C$13,2,1))) -> 3 | L4: =1+(E4>=Calc!$C$16)+(E4>=Calc!$C$17)+(E4>=Calc!$C$18) -> 3 | M4: =IF(AND(K4=4,L4>=3),"Champions",IF(AND(K4=3,L4>=3),"Loyal",IF(K4>=3,"Recent / New",IF(L4>=3,"At Risk","Hibernating / Lost")))) -> Loyal | N4: =IF(AND(Calc!$C$2<=2009,Calc!$C$3>=2009),F4,0)+IF(AND(Calc!$C$2<=2010,Calc!$C$3>=2010),G4,0)+IF(AND(Calc!$C$2<=2011,Calc!$C$3>=2011),H4,0) -> 1658.4 | O4: =IF(AND(N4>0,OR(Calc!$C$4="*",B4=Calc!$C$4)),N4+ROW()*0.000000001,0) -> 1658.4
A5: 12349 | B5: Italy | C5: 40297 | D5: 40868 | E5: 3 | F5: -24.15 | G5: 2221.14 | H5: 1457.55 | I5: =SUM(F5:H5) -> 3654.54 | J5: =Calc!$C$5-D5 -> 19 | K5: =IF(J5<=Calc!$C$11,4,IF(J5<=Calc!$C$12,3,IF(J5<=Calc!$C$13,2,1))) -> 4 | L5: =1+(E5>=Calc!$C$16)+(E5>=Calc!$C$17)+(E5>=Calc!$C$18) -> 2 | M5: =IF(AND(K5=4,L5>=3),"Champions",IF(AND(K5=3,L5>=3),"Loyal",IF(K5>=3,"Recent / New",IF(L5>=3,"At Risk","Hibernating / Lost")))) -> Recent / New | N5: =IF(AND(Calc!$C$2<=2009,Calc!$C$3>=2009),F5,0)+IF(AND(Calc!$C$2<=2010,Calc!$C$3>=2010),G5,0)+IF(AND(Calc!$C$2<=2011,Calc!$C$3>=2011),H5,0) -> 3654.54 | O5: =IF(AND(N5>0,OR(Calc!$C$4="*",B5=Calc!$C$4)),N5+ROW()*0.000000001,0) -> 3654.54
A6: 12350 | B6: Norway | C6: 40576 | D6: 40576 | E6: 1 | F6: 0 | G6: 0 | H6: 294.4 | I6: =SUM(F6:H6) -> 294.4 | J6: =Calc!$C$5-D6 -> 311 | K6: =IF(J6<=Calc!$C$11,4,IF(J6<=Calc!$C$12,3,IF(J6<=Calc!$C$13,2,1))) -> 2 | L6: =1+(E6>=Calc!$C$16)+(E6>=Calc!$C$17)+(E6>=Calc!$C$18) -> 1 | M6: =IF(AND(K6=4,L6>=3),"Champions",IF(AND(K6=3,L6>=3),"Loyal",IF(K6>=3,"Recent / New",IF(L6>=3,"At Risk","Hibernating / Lost")))) -> Hibernating / Lost | N6: =IF(AND(Calc!$C$2<=2009,Calc!$C$3>=2009),F6,0)+IF(AND(Calc!$C$2<=2010,Calc!$C$3>=2010),G6,0)+IF(AND(Calc!$C$2<=2011,Calc!$C$3>=2011),H6,0) -> 294.4 | O6: =IF(AND(N6>0,OR(Calc!$C$4="*",B6=Calc!$C$4)),N6+ROW()*0.000000001,0) -> 294.4
A7: 12351 | B7: Unspecified | C7: 40511 | D7: 40511 | E7: 1 | F7: 0 | G7: 300.93 | H7: 0 | I7: =SUM(F7:H7) -> 300.93 | J7: =Calc!$C$5-D7 -> 376 | K7: =IF(J7<=Calc!$C$11,4,IF(J7<=Calc!$C$12,3,IF(J7<=Calc!$C$13,2,1))) -> 2 | L7: =1+(E7>=Calc!$C$16)+(E7>=Calc!$C$17)+(E7>=Calc!$C$18) -> 1 | M7: =IF(AND(K7=4,L7>=3),"Champions",IF(AND(K7=3,L7>=3),"Loyal",IF(K7>=3,"Recent / New",IF(L7>=3,"At Risk","Hibernating / Lost")))) -> Hibernating / Lost | N7: =IF(AND(Calc!$C$2<=2009,Calc!$C$3>=2009),F7,0)+IF(AND(Calc!$C$2<=2010,Calc!$C$3>=2010),G7,0)+IF(AND(Calc!$C$2<=2011,Calc!$C$3>=2011),H7,0) -> 300.93 | O7: =IF(AND(N7>0,OR(Calc!$C$4="*",B7=Calc!$C$4)),N7+ROW()*0.000000001,0) -> 300.93
A8: 12352 | B8: Norway | C8: 40494 | D8: 40850 | E8: 9 | F8: 0 | G8: 343.8 | H8: 1265.41 | I8: =SUM(F8:H8) -> 1609.21 | J8: =Calc!$C$5-D8 -> 37 | K8: =IF(J8<=Calc!$C$11,4,IF(J8<=Calc!$C$12,3,IF(J8<=Calc!$C$13,2,1))) -> 3 | L8: =1+(E8>=Calc!$C$16)+(E8>=Calc!$C$17)+(E8>=Calc!$C$18) -> 4 | M8: =IF(AND(K8=4,L8>=3),"Champions",IF(AND(K8=3,L8>=3),"Loyal",IF(K8>=3,"Recent / New",IF(L8>=3,"At Risk","Hibernating / Lost")))) -> Loyal | N8: =IF(AND(Calc!$C$2<=2009,Calc!$C$3>=2009),F8,0)+IF(AND(Calc!$C$2<=2010,Calc!$C$3>=2010),G8,0)+IF(AND(Calc!$C$2<=2011,Calc!$C$3>=2011),H8,0) -> 1609.21 | O8: =IF(AND(N8>0,OR(Calc!$C$4="*",B8=Calc!$C$4)),N8+ROW()*0.000000001,0) -> 1609.21
A9: 12353 | B9: Bahrain | C9: 40478 | D9: 40682 | E9: 2 | F9: 0 | G9: 317.76 | H9: 89 | I9: =SUM(F9:H9) -> 406.76 | J9: =Calc!$C$5-D9 -> 205 | K9: =IF(J9<=Calc!$C$11,4,IF(J9<=Calc!$C$12,3,IF(J9<=Calc!$C$13,2,1))) -> 2 | L9: =1+(E9>=Calc!$C$16)+(E9>=Calc!$C$17)+(E9>=Calc!$C$18) -> 2 | M9: =IF(AND(K9=4,L9>=3),"Champions",IF(AND(K9=3,L9>=3),"Loyal",IF(K9>=3,"Recent / New",IF(L9>=3,"At Risk","Hibernating / Lost")))) -> Hibernating / Lost | N9: =IF(AND(Calc!$C$2<=2009,Calc!$C$3>=2009),F9,0)+IF(AND(Calc!$C$2<=2010,Calc!$C$3>=2010),G9,0)+IF(AND(Calc!$C$2<=2011,Calc!$C$3>=2011),H9,0) -> 406.76 | O9: =IF(AND(N9>0,OR(Calc!$C$4="*",B9=Calc!$C$4)),N9+ROW()*0.000000001,0) -> 406.76
A10: 12354 | B10: Spain | C10: 40654 | D10: 40654 | E10: 1 | F10: 0 | G10: 0 | H10: 1079.4 | I10: =SUM(F10:H10) -> 1079.4 | J10: =Calc!$C$5-D10 -> 233 | K10: =IF(J10<=Calc!$C$11,4,IF(J10<=Calc!$C$12,3,IF(J10<=Calc!$C$13,2,1))) -> 2 | L10: =1+(E10>=Calc!$C$16)+(E10>=Calc!$C$17)+(E10>=Calc!$C$18) -> 1 | M10: =IF(AND(K10=4,L10>=3),"Champions",IF(AND(K10=3,L10>=3),"Loyal",IF(K10>=3,"Recent / New",IF(L10>=3,"At Risk","Hibernating / Lost")))) -> Hibernating / Lost | N10: =IF(AND(Calc!$C$2<=2009,Calc!$C$3>=2009),F10,0)+IF(AND(Calc!$C$2<=2010,Calc!$C$3>=2010),G10,0)+IF(AND(Calc!$C$2<=2011,Calc!$C$3>=2011),H10,0) -> 1079.4 | O10: =IF(AND(N10>0,OR(Calc!$C$4="*",B10=Calc!$C$4)),N10+ROW()*0.000000001,0) -> 1079.4
A11: 12355 | B11: Bahrain | C11: 40319 | D11: 40672 | E11: 2 | F11: 0 | G11: 488.21 | H11: 459.4 | I11: =SUM(F11:H11) -> 947.61 | J11: =Calc!$C$5-D11 -> 215 | K11: =IF(J11<=Calc!$C$11,4,IF(J11<=Calc!$C$12,3,IF(J11<=Calc!$C$13,2,1))) -> 2 | L11: =1+(E11>=Calc!$C$16)+(E11>=Calc!$C$17)+(E11>=Calc!$C$18) -> 2 | M11: =IF(AND(K11=4,L11>=3),"Champions",IF(AND(K11=3,L11>=3),"Loyal",IF(K11>=3,"Recent / New",IF(L11>=3,"At Risk","Hibernating / Lost")))) -> Hibernating / Lost | N11: =IF(AND(Calc!$C$2<=2009,Calc!$C$3>=2009),F11,0)+IF(AND(Calc!$C$2<=2010,Calc!$C$3>=2010),G11,0)+IF(AND(Calc!$C$2<=2011,Calc!$C$3>=2011),H11,0) -> 947.61 | O11: =IF(AND(N11>0,OR(Calc!$C$4="*",B11=Calc!$C$4)),N11+ROW()*0.000000001,0) -> 947.61
A12: 12356 | B12: Portugal | C12: 40462 | D12: 40864 | E12: 6 | F12: 0 | G12: 3124.3 | H12: 2487.43 | I12: =SUM(F12:H12) -> 5611.73 | J12: =Calc!$C$5-D12 -> 23 | K12: =IF(J12<=Calc!$C$11,4,IF(J12<=Calc!$C$12,3,IF(J12<=Calc!$C$13,2,1))) -> 4 | L12: =1+(E12>=Calc!$C$16)+(E12>=Calc!$C$17)+(E12>=Calc!$C$18) -> 3 | M12: =IF(AND(K12=4,L12>=3),"Champions",IF(AND(K12=3,L12>=3),"Loyal",IF(K12>=3,"Recent / New",IF(L12>=3,"At Risk","Hibernating / Lost")))) -> Champions | N12: =IF(AND(Calc!$C$2<=2009,Calc!$C$3>=2009),F12,0)+IF(AND(Calc!$C$2<=2010,Calc!$C$3>=2010),G12,0)+IF(AND(Calc!$C$2<=2011,Calc!$C$3>=2011),H12,0) -> 5611.73 | O12: =IF(AND(N12>0,OR(Calc!$C$4="*",B12=Calc!$C$4)),N12+ROW()*0.000000001,0) -> 5611.73
A13: 12357 | B13: Switzerland | C13: 40498 | D13: 40853 | E13: 2 | F13: 0 | G13: 11229.99 | H13: 6207.67 | I13: =SUM(F13:H13) -> 17437.66 | J13: =Calc!$C$5-D13 -> 34 | K13: =IF(J13<=Calc!$C$11,4,IF(J13<=Calc!$C$12,3,IF(J13<=Calc!$C$13,2,1))) -> 3 | L13: =1+(E13>=Calc!$C$16)+(E13>=Calc!$C$17)+(E13>=Calc!$C$18) -> 2 | M13: =IF(AND(K13=4,L13>=3),"Champions",IF(AND(K13=3,L13>=3),"Loyal",IF(K13>=3,"Recent / New",IF(L13>=3,"At Risk","Hibernating / Lost")))) -> Recent / New | N13: =IF(AND(Calc!$C$2<=2009,Calc!$C$3>=2009),F13,0)+IF(AND(Calc!$C$2<=2010,Calc!$C$3>=2010),G13,0)+IF(AND(Calc!$C$2<=2011,Calc!$C$3>=2011),H13,0) -> 17437.66 | O13: =IF(AND(N13>0,OR(Calc!$C$4="*",B13=Calc!$C$4)),N13+ROW()*0.000000001,0) -> 17437.66
... A5853: 18287 | B5853: United Kingdom | C5853: 40315 | D5853: 40844 | E5853: 7 | F5853: -5.1 | G5853: 2295.71 | H5853: 1837.28 | I5853: =SUM(F5853:H5853) -> 4127.89 | J5853: =Calc!$C$5-D5853 -> 43 | K5853: =IF(J5853<=Calc!$C$11,4,IF(J5853<=Calc!$C$12,3,IF(J5853<=Calc!$C$13,2,1))) -> 3 | L5853: =1+(E5853>=Calc!$C$16)+(E5853>=Calc!$C$17)+(E5853>=Calc!$C$18) -> 3 | M5853: =IF(AND(K5853=4,L5853>=3),"Champions",IF(AND(K5853=3,L5853>=3),"Loyal",IF(K5853>=3,"Recent / New",IF(L5853>=3,"At Risk","Hibernating / Lost")))) -> Loyal | N5853: =IF(AND(Calc!$C$2<=2009,Calc!$C$3>=2009),F5853,0)+IF(AND(Calc!$C$2<=2010,Calc!$C$3>=2010),G5853,0)+IF(AND(Calc!$C$2<=2011,Calc!$C$3>=2011),H5853,0) -> 4127.89 | O5853: =IF(AND(N5853>0,OR(Calc!$C$4="*",B5853=Calc!$C$4)),N5853+ROW()*0.000000001,0) -> 4127.89

Sheet Fact_Monthly
A1: Month | B1: Year | C1: MonthNum | D1: Country | E1: Sales | F1: Returns | G1: Orders | H1: Units
A2: 40148 | B2: 2009 | C2: 12 | D2: Australia | E2: 271.1 | F2: 220.85 | G2: 2 | H2: 160
A3: 40148 | B3: 2009 | C3: 12 | D3: Austria | E3: 1918.34 | F3: 0 | G3: 2 | H3: 562
A4: 40148 | B4: 2009 | C4: 12 | D4: Belgium | E4: 287.6 | F4: 0 | G4: 2 | H4: 150
A5: 40148 | B5: 2009 | C5: 12 | D5: Channel Islands | E5: 989.18 | F5: 43.8 | G5: 1 | H5: 439
A6: 40148 | B6: 2009 | C6: 12 | D6: Cyprus | E6: 3541.68 | F6: 131.9 | G6: 4 | H6: 1572
A7: 40148 | B7: 2009 | C7: 12 | D7: Denmark | E7: 1365.66 | F7: 17.2 | G7: 2 | H7: 570
A8: 40148 | B8: 2009 | C8: 12 | D8: EIRE | E8: 18946.49 | F8: 168.55 | G8: 19 | H8: 9406
A9: 40148 | B9: 2009 | C9: 12 | D9: Finland | E9: 469.08 | F9: 0 | G9: 1 | H9: 132
A10: 40148 | B10: 2009 | C10: 12 | D10: France | E10: 5873.69 | F10: 876.65 | G10: 13 | H10: 3652
A11: 40148 | B11: 2009 | C11: 12 | D11: Germany | E11: 8768.27 | F11: 314.23 | G11: 17 | H11: 4726
A12: 40148 | B12: 2009 | C12: 12 | D12: Greece | E12: 610.95 | F12: 0 | G12: 1 | H12: 441
A13: 40148 | B13: 2009 | C13: 12 | D13: Italy | E13: 422.35 | F13: 24.15 | G13: 1 | H13: 157
... A583: 40878 | B583: 2011 | C583: 12 | D583: United Kingdom | E583: 571280.33 | F583: 172933.79 | G583: 744 | H583: 285792

Sheet Fact_Product
A1: ProdID | B1: Country | C1: Year | D1: Revenue | E1: Units | G1: ProdID | H1: StockCode | I1: Description
A2: 1 | B2: Australia | C2: 2010 | D2: 927 | E2: 84 | G2: 1 | H2: 22423 | I2: REGENCY CAKESTAND 3 TIER
A3: 1 | B3: Australia | C3: 2011 | D3: 1978.2 | E3: 180 | G3: 2 | H3: 85123A | I3: WHITE HANGING HEART T-LIGHT HOLDER
A4: 1 | B4: Austria | C4: 2011 | D4: 51 | E4: 4 | G4: 3 | H4: 85099B | I4: JUMBO BAG RED RETROSPOT
A5: 1 | B5: Bahrain | C5: 2011 | D5: 25.5 | E5: 2 | G5: 4 | H5: 47566 | I5: PARTY BUNTING
A6: 1 | B6: Belgium | C6: 2010 | D6: 114.75 | E6: 9 | G6: 5 | H6: 84879 | I6: ASSORTED COLOUR BIRD ORNAMENT
A7: 1 | B7: Belgium | C7: 2011 | D7: 548.25 | E7: 43 | G7: 6 | H7: 22086 | I7: PAPER CHAIN KIT 50'S CHRISTMAS
A8: 1 | B8: Brazil | C8: 2011 | D8: 175.2 | E8: 16 | G8: 7 | H8: 79321 | I8: CHILLI LIGHTS
A9: 1 | B9: Canada | C9: 2011 | D9: 12.75 | E9: 1 | G9: 8 | H9: 22197 | I9: SMALL POPCORN HOLDER
A10: 1 | B10: Channel Islands | C10: 2010 | D10: 267.75 | E10: 21 | G10: 9 | H10: 22386 | I10: JUMBO BAG PINK POLKADOT
A11: 1 | B11: Channel Islands | C11: 2011 | D11: 517.8 | E11: 44 | G11: 10 | H11: 84347 | I11: ROTATING SILVER ANGELS T-LIGHT HLDR
A12: 1 | B12: Cyprus | C12: 2010 | D12: 567.15 | E12: 49 | G12: 11 | H12: 20725 | I12: LUNCH BAG RED RETROSPOT
A13: 1 | B13: Cyprus | C13: 2011 | D13: 382.5 | E13: 30 | G13: 12 | H13: 85099F | I13: JUMBO BAG STRAWBERRY
... A501: 17 | B501: Australia | C501: 2010 | D501: 39 | E501: 20 | G501: 500 | H501: 22121 | I501: NOEL WOODEN BLOCK LETTERS
A502: 17 | B502: Australia | C502: 2011 | D502: 20.8 | E502: 10
A503: 17 | B503: Austria | C503: 2010 | D503: 39 | E503: 20
A504: 17 | B504: Austria | C504: 2011 | D504: 39 | E504: 20
A505: 17 | B505: Belgium | C505: 2010 | D505: 78 | E505: 40
A506: 17 | B506: Belgium | C506: 2011 | D506: 104 | E506: 50
A507: 17 | B507: Channel Islands | C507: 2010 | D507: 19.5 | E507: 10
A508: 17 | B508: Cyprus | C508: 2010 | D508: 19.5 | E508: 10
A509: 17 | B509: Cyprus | C509: 2011 | D509: 40.3 | E509: 20
A510: 17 | B510: Denmark | C510: 2010 | D510: 204 | E510: 120
A511: 17 | B511: Denmark | C511: 2011 | D511: 39 | E511: 20
A512: 17 | B512: EIRE | C512: 2009 | D512: 19.5 | E512: 10
A513: 17 | B513: EIRE | C513: 2010 | D513: 167.7 | E513: 86
... A11612: 500 | B11612: Unspecified | C11612: 2010 | D11612: 5.95 | E11612: 1

Sheet Fact_Time
A1: Year | B1: Country | C1: Weekday | D1: Hour | E1: Sales
A2: 2009 | B2: Australia | C2: 2 | D2: 10 | E2: 196.1
A3: 2009 | B3: Australia | C3: 5 | D3: 12 | E3: 75
A4: 2009 | B4: Austria | C4: 2 | D4: 7 | E4: 1429.83
A5: 2009 | B5: Austria | C5: 2 | D5: 12 | E5: 488.51
A6: 2009 | B6: Belgium | C6: 4 | D6: 11 | E6: 8.5
A7: 2009 | B7: Belgium | C7: 7 | D7: 10 | E7: 279.1
A8: 2009 | B8: Channel Islands | C8: 5 | D8: 9 | E8: 989.18
A9: 2009 | B9: Cyprus | C9: 1 | D9: 8 | E9: 1066.36
A10: 2009 | B10: Cyprus | C10: 3 | D10: 15 | E10: 78.2
A11: 2009 | B11: Cyprus | C11: 5 | D11: 12 | E11: 1636.43
A12: 2009 | B12: Cyprus | C12: 6 | D12: 13 | E12: 760.69
A13: 2009 | B13: Denmark | C13: 2 | D13: 10 | E13: 357.66
... A1485: 2011 | B1485: Unspecified | C1485: 5 | D1485: 16 | E1485: 626.93

Sheet Lists
A1: Countries | C1: Years | E1: Metrics | G1: Weekdays | I1: Segments
A2: All Countries | C2: All Years | E2: Net Revenue | G2: Mon | I2: Champions
A3: United Kingdom | C3: 2009 | E3: Orders | G3: Tue | I3: Loyal
A4: EIRE | C4: 2010 | E4: Units Sold | G4: Wed | I4: Recent / New
A5: Netherlands | C5: 2011 | E5: Avg Order Value | G5: Thu | I5: At Risk
A6: Germany | G6: Fri | I6: Hibernating / Lost
A7: France | G7: Sat
A8: Australia | G8: Sun
A9: Switzerland
A10: Spain
A11: Sweden
A12: Denmark
A13: Belgium
A14: Portugal
A15: Channel Islands
A16: Japan
A17: Norway
A18: Italy
A19: Finland
A20: Cyprus
... A45: Nigeria
